Workbook

Sheet Risk_Register_V1
A1: Risk_ID | B1: Risk description | C1: Impact description | D1: Impact Level (1-5) | E1: Probability Level (1-5) | F1: Priority Level (Impact * probability) | G1: Mitigation Notes | H1: Status | I1: Notes | J1: Date Identified
A2: Risk_01 | B2: Lack of experience | C2: Not all team have computer engineering background which might reduce output efficiency and quality | D2: 5 | E2: 5 | F2: =D2*E2 -> 25 | G2: Prioritize crash courses and training sessions for the team | H2: Open | J2: =IF(A2<>"", IF(J2="", TODAY(), J2), "") -> 46111
A3: Risk_02 | B3: Burnout and time management risk | C3: Team is commited to projects,exams and other courses | D3: 4 | E3: 4 | F3: =D3*E3 -> 16 | G3: Distribute tasks among teams based on previous technical backgrounds to increase productivity and conduct daily meetings to monitor progress | H3: Open | J3: =IF(A3<>"", IF(J3="", TODAY(), J3), "") -> 46111
A4: Risk_03 | B4: Communication issues | C4: Team memebers might face internet connection issues as most of the work and meetings will be done online | D4: 3 | E4: 1 | F4: =D4*E4 -> 3 | G4: Team can utilize coworking spaces for internet connection or ensure all team members have stable internet connection | H4: Open | J4: =IF(A4<>"", IF(J4="", TODAY(), J4), "") -> 46111
A5: Risk_04 | B5: Tools knowledge risks | C5: Not all team members have used tools important for the project such as jira,github and other technical tools | D5: 4 | E5: 3 | F5: =D5*E5 -> 12 | G5: Sharing knowledge among team members and take courses if necessary | H5: Open | J5: =IF(A5<>"", IF(J5="", TODAY(), J5), "") -> 46111
A6: Risk_05 | B6: Tools licence risks | C6: Some important tools might need licence to use which might delay work quality | D6: 2 | E6: 2 | F6: =D6*E6 -> 4 | G6: Use alternative high quality free tools available | H6: Open | J6: =IF(A6<>"", IF(J6="", TODAY(), J6), "") -> 46111
A7: Risk_06 | B7: Members availability | C7: Team memebers might not be available due to sickness or personal issues | D7: 5 | E7: 3 | F7: =D7*E7 -> 15 | G7: Team members should know each other's task progress and ensure work transparency and have alternative plans to compensate for other members being unavailable | H7: Open | J7: =IF(A7<>"", IF(J7="", TODAY(), J7), "") -> 46111
A8: Risk_07 | B8: Client communication risks | C8: Client meets with team members only once a week which affects constant feedback and consultation | D8: 4 | E8: 5 | F8: =D8*E8 -> 20 | G8: Before each sprint, team members should have all questions ready and after the sprint all questions should be answered | H8: Open | J8: =IF(A8<>"", IF(J8="", TODAY(), J8), "") -> 46111
A9: Risk_08 | B9: Client change requests | C9: Client might ask for a change request which might disturb work flow | D9: 5 | E9: 4 | F9: =D9*E9 -> 20 | G9: Team should analyze and priortitize change requests based on importance and should have agreement and rules for change requests | H9: Open | J9: =IF(A9<>"", IF(J9="", TODAY(), J9), "") -> 46111
A10: Risk_09 | B10: Technical debt risks | C10: taking the easy way during SDLC might cause increase in rework cost | D10: 5 | E10: 5 | F10: =D10*E10 -> 25 | G10: Conduct rigorous peer reviews and ensure each step is done efficiently before moving to the next step | H10: Open | J10: =IF(A10<>"", IF(J10="", TODAY(), J10), "") -> 46111
F11: =D11*E11 -> 0 | J11: =IF(A11<>"", IF(J11="", TODAY(), J11), "")
F12: =D12*E12 -> 0 | J12: =IF(A12<>"", IF(J12="", TODAY(), J12), "")
F13: =D13*E13 -> 0 | J13: =IF(A13<>"", IF(J13="", TODAY(), J13), "")
F14: =D14*E14 -> 0 | J14: =IF(A14<>"", IF(J14="", TODAY(), J14), "")
F15: =D15*E15 -> 0 | J15: =IF(A15<>"", IF(J15="", TODAY(), J15), "")
F16: =D16*E16 -> 0 | J16: =IF(A16<>"", IF(J16="", TODAY(), J16), "")
F17: =D17*E17 -> 0 | J17: =IF(A17<>"", IF(J17="", TODAY(), J17), "")
F18: =D18*E18 -> 0 | J18: =IF(A18<>"", IF(J18="", TODAY(), J18), "")
F19: =D19*E19 -> 0 | J19: =IF(A19<>"", IF(J19="", TODAY(), J19), "")
F20: =D20*E20 -> 0 | J20: =IF(A20<>"", IF(J20="", TODAY(), J20), "")
F21: =D21*E21 -> 0 | J21: =IF(A21<>"", IF(J21="", TODAY(), J21), "")
F22: =D22*E22 -> 0 | J22: =IF(A22<>"", IF(J22="", TODAY(), J22), "")
... F55: =D55*E55 -> 0 | J55: =IF(A55<>"", IF(J55="", TODAY(), J55), "")
J56: =IF(A56<>"", IF(J56="", TODAY(), J56), "")
J57: =IF(A57<>"", IF(J57="", TODAY(), J57), "")
J58: =IF(A58<>"", IF(J58="", TODAY(), J58), "")
J59: =IF(A59<>"", IF(J59="", TODAY(), J59), "")
J60: =IF(A60<>"", IF(J60="", TODAY(), J60), "")
J61: =IF(A61<>"", IF(J61="", TODAY(), J61), "")
J62: =IF(A62<>"", IF(J62="", TODAY(), J62), "")
J63: =IF(A63<>"", IF(J63="", TODAY(), J63), "")
J64: =IF(A64<>"", IF(J64="", TODAY(), J64), "")
J65: =IF(A65<>"", IF(J65="", TODAY(), J65), "")

Sheet SIQs
A1: Module/Feature/Sub-feature | B1: SIQ ID | C1: Question | D1: Proposed answer | E1: Customer answer
A2: Login | B2: ="SIQ-" & (ROW()-1) -> SIQ-1 | C2: What are the login feature fields? | D2: Login feature fields are: -Email and Password fields - Login button -Link for user to register if not already registered | E2: Customer agrees
B3: ="SIQ-" & (ROW()-1) -> SIQ-2 | C3: What happens if user leaves fields empty ? | D3: Error message appears under each empty field saying "This field is required" | E3: Customer agrees
B4: ="SIQ-" & (ROW()-1) -> SIQ-3 | C4: What happens when user enters valid credentials? | D4: User is redirected to Explore page | E4: Customer agrees
B5: ="SIQ-" & (ROW()-1) -> SIQ-4 | C5: What happens when user enters invalid credentials with correct email formatting for the email or password fields? | D5: User is prevented from logging in and an error message shows above login button saying "invalid email or password" | E5: Customer agrees
B6: ="SIQ-" & (ROW()-1) -> SIQ-5 | C6: What happens when user enters invalid email format in the email field? | D6: Any invalid email format should be not be allowed (eg. missing @,missing domain,etc..) with error message "invalid email format" | E6: Customer agrees
B7: ="SIQ-" & (ROW()-1) -> SIQ-6 | C7: What happens when user clicks on Create account button? | D7: User is redirected to Registration page | E7: Customer agrees
B8: ="SIQ-" & (ROW()-1) -> SIQ-7 | C8: What happens when admin logs in successfully? | D8: Admin is redirected to User management page | E8: Customer agrees
B9: ="SIQ-" & (ROW()-1) -> SIQ-8 | C9: Should admin have a separate login page or the same one as the user ? | D9: The same one as the user. | E9: Customer agrees
B10: ="SIQ-" & (ROW()-1) -> SIQ-9 | C10: Is there a rate limit for amount of login attempts ? | D10: Yes, user is locked out after 5 wrong attempts with message appearing above login button "Please try again in 60 seconds" and countdown until message disappears. In the lock out period login button is disabled. | E10: Customer agrees
A11: Register | B11: ="SIQ-" & (ROW()-1) -> SIQ-10 | C11: What are the register feature fields? | D11: Register feature fields are : -First name -Last name -Email -Password -Confirm password -Register button -Link to redirect user if already having an account to login | E11: Customer agrees
B12: ="SIQ-" & (ROW()-1) -> SIQ-11 | C12: What happens if user leaves any field empty? | D12: Error message appears under each empty field saying "This field is required" | E12: Customer agrees
B13: ="SIQ-" & (ROW()-1) -> SIQ-12 | C13: Is there a minimum or maximum number of characters for any field? | D13: -name fields : max 50 char , min 2 char, error message: " First name/Last name must be between 2 to 50 characters" -password field: min 8 characters ,error message: "password should be at least 8 characters long" | E13: Customer agrees
B14: ="SIQ-" & (ROW()-1) -> SIQ-13 | C14: Are there any password complexity requirements ? | D14: Yes at least one small letter, one capital letter, one number and one special character | E14: Customer agrees
B15: ="SIQ-" & (ROW()-1) -> SIQ-14 | C15: What happens when user enters password that doesn't meet complexity | D15: Message appears under password field saying "password should have one small letter,one capital letter,one number and one special character" | E15: Customer agrees
B16: ="SIQ-" & (ROW()-1) -> SIQ-15 | C16: What happens when user enters password with length below minimum? | D16: Error message appears under pasword field "Password must be at least 8 characters long" | E16: Customer agrees
B17: ="SIQ-" & (ROW()-1) -> SIQ-16 | C17: What happens when user enters password that doesn't match password in confirm password field? | D17: Error message shows under confirm password field "Password doesn't match" | E17: Customer agrees
B18: ="SIQ-" & (ROW()-1) -> SIQ-17 | C18: What happens when user enters invalid email format in the email field? | D18: Any invalid email format should be not be allowed (eg. missing @,missing domain,etc..) | E18: Customer agrees
B19: ="SIQ-" & (ROW()-1) -> SIQ-18 | C19: Can name fields contain numbers or special characters? | D19: Only alphabetic characters allowed | E19: Customer agrees
B20: ="SIQ-" & (ROW()-1) -> SIQ-19 | C20: Should user be redirected to Explore page or login page after successful registration? | D20: Explore page | E20: Customer agrees
B21: ="SIQ-" & (ROW()-1) -> SIQ-20 | C21: What happens if a user enters an email that is already registered ? | D21: An error message shows above Register button "Email already has an account" | E21: Customer agrees
B22: ="SIQ-" & (ROW()-1) -> SIQ-21 | C22: What happens when user clicks on Login link? | D22: User is redirected to login page | E22: Customer agrees
A23: Explore/Home | B23: ="SIQ-" & (ROW()-1) -> SIQ-22 | C23: What are the main features in Explore page other than gallery of top travel destinations? | D23: The home screen contains the following features: -Navigation bar with these nav links/buttons : Explore, Find flights,My bookings , Logout button and current page should be underlined -A section where user can choose from touristic countries -At max 9 images for each country which update dynamically based on user country choice -"View tour" button to navigate to page with details for each page -customer reviews section for the website at the bottom | E23: Customer agrees
B24: ="SIQ-" & (ROW()-1) -> SIQ-23 | C24: Where should user be redirected after clicking on Logout button? | D24: User should be redirected to login page | E24: Customer agrees
A25: Destination Details | B25: ="SIQ-" & (ROW()-1) -> SIQ-24 | C25: What are the components/features of this page? | D25: -A banner/image for the destination as shown in explore page -Text that describes the place -Labeled pictures to show remarkable views of the destination | E25: Customer agrees
B26: ="SIQ-" & (ROW()-1) -> SIQ-25 | C26: - what happens when the user clicks on the Booking button? | D26: - Booking button to take user to Find flights page to start the booking flow after viewing the destination | E26: Customer agrees
A27: Flight Search Page / Find Flights | B27: ="SIQ-" & (ROW()-1) -> SIQ-26 | C27: Does the page include only the required fields (Departure, Destination, Dates) without extra elements? | D27: The page contains exactly three input fields and a Search button as specified | E27: Customer shows no objections.
B28: ="SIQ-" & (ROW()-1) -> SIQ-27 | C28: Does the system validate that all fields (Departure, Destination, Dates) are filled before searching? | D28: The system prevents search and displays an error message under field if any field is empty | E28: Customer shows no objections.
B29: ="SIQ-" & (ROW()-1) -> SIQ-28 | C29: Can the user select the same city for Departure and Destination? | D29: The system prevents selecting the same location and shows a warning message | E29: Customer shows no objections.
B30: ="SIQ-" & (ROW()-1) -> SIQ-29 | C30: Does clicking the Search button display flight results on the same page? | D30: Results are displayed dynamically on the same page without redirection | E30: Customer shows no objections.
B31: ="SIQ-" & (ROW()-1) -> SIQ-30 | C31: Does the "Select Flight" button navigate the user to the payment page? | D31: Upon selecting a flight, the user is redirected to the payment page | E31: Customer shows no objections.
B32: ="SIQ-" & (ROW()-1) -> SIQ-31 | C32: What happens if no flights are found? | D32: The system displays a "No search results" message | E32: Customer shows no objections.
A33: Passenger Details | B33: ="SIQ-" & (ROW()-1) -> SIQ-32 | C33: What fields should be present? | D33: Full name, passport number, and date of birth | E33: Customer shows no objections.
B34: ="SIQ-" & (ROW()-1) -> SIQ-33 | C34: What validations are required? | D34: Each field is mandatory and cannot be left empty | E34: Customer shows no objections.
B35: ="SIQ-" & (ROW()-1) -> SIQ-34 | C35: What happens if a required field is empty? | D35: A validation error message is displayed under the corresponding field | E35: Customer shows no objections.
B36: ="SIQ-" & (ROW()-1) -> SIQ-35 | C36: What validation is applied to Full Name field? | D36: Accepts alphabetic characters only (A–Z) | E36: Customer shows no objections.
B37: ="SIQ-" & (ROW()-1) -> SIQ-36 | C37: What are the length constraints for Full Name? | D37: Minimum 3 characters and maximum 30 characters | E37: Customer shows no objections.
B38: ="SIQ-" & (ROW()-1) -> SIQ-37 | C38: What validation is applied to passport number? | D38: Accepts alphanumeric characters only | E38: Customer shows no objections.
B39: ="SIQ-" & (ROW()-1) -> SIQ-38 | C39: Are spaces allowed in passport number? | D39: No, spaces are not allowed | E39: Customer shows no objections.
B40: ="SIQ-" & (ROW()-1) -> SIQ-39 | C40: Can the user enter a future date of birth? | D40: No, date of birth must be in the past | E40: Customer shows no objections.
...

Sheet Test Cases
A1: TesTCASE ID | B1: Test Cases Title | C1: valid/invaldid | D1: Environment | E1: Pre-condition | F1: Steps | G1: Test Data | H1: Expected Results | I1: Post Condition | J1: TC Status | K1: Attachment | L1: Requirement ID | M1: Type | N1: Tester | O1: Comment
A2: TC_Registration_001 | B2: Verify registration feature in case of user registering with valid data for all fields | C2: valid | E2: User is already on registration page | F2: 1-Enter first name in First name field 2-Enter last name in Last name field 3-Enter email in Email field 4-Enter password in password field 5-Enter confirm password in Confirm password field 6-Click on Create account button | H2: User should successfully be redirected to Explore/home page | J2: Draft | L2: UR-09 | M2: Functional | N2: Ahmed Zahran
A3: TC_Registration_002 | B3: Verify registration feature in case of user clicking on login link | C3: valid | E3: User is already on registration page | F3: 1-Navigate to login link 2- Click on login link | H3: User should successfully be redirected to Login page | J3: Draft | L3: UR-10 | M3: Functional | N3: Ahmed Zahran
A4: TC_Registration_003 | B4: Verify registration feature in case of user entering First name that is exactly the minimum allowed character length | C4: valid | E4: User is already on registration page | F4: 1-Enter first name in First name field 2-Enter last name in Last name field 3-Enter email in Email field 4-Enter password in password field 5-Enter confirm password in Confirm password field 6-Click on Create account button | H4: User should successfully be redirected to Explore/home page | J4: Draft | L4: UR-02 | M4: Functional | N4: Ahmed Zahran
A5: TC_Registration_004 | B5: Verify registration feature in case of user entering First name that is exactly the maximim allowed character length | C5: valid | E5: User is already on registration page | F5: 1-Enter first name in First name field 2-Enter last name in Last name field 3-Enter email in Email field 4-Enter password in password field 5-Enter confirm password in Confirm password field 6-Click on Create account button | H5: User should successfully be redirected to Explore/home page | J5: Draft | L5: UR-02 | M5: Functional | N5: Ahmed Zahran
A6: TC_Registration_005 | B6: Verify registration feature in case of user entering Last name that is exactly the minimum allowed character length | C6: valid | E6: User is already on registration page | F6: 1-Enter first name in First name field 2-Enter last name in Last name field 3-Enter email in Email field 4-Enter password in password field 5-Enter confirm password in Confirm password field 6-Click on Create account button | H6: User should successfully be redirected to Explore/home page | J6: Draft | L6: UR-02 | M6: Functional | N6: Ahmed Zahran
A7: TC_Registration_006 | B7: Verify registration feature in case of user entering Last name that is exactly the maxiimum allowed character length | C7: valid | E7: User is already on registration page | F7: "1-Enter first name in First name field 2-Enter last name in Last name field 3-Enter email in Email field 4-Enter password in password field 5-Enter confirm password in Confirm password field 6-Click on Create account button" | H7: User should successfully be redirected to Explore/home page | J7: Draft | L7: UR-02 | M7: Functional | N7: Ahmed Zahran
A8: TC_Registration_007 | B8: Verfiy registration feature in case of user entering password that is exactly the minimum allowed character length | C8: valid | E8: User is already on registration page | F8: 1-Enter first name in First name field 2-Enter last name in Last name field 3-Enter email in Email field 4-Enter password in password field 5-Enter confirm password in Confirm password field 6-Click on Create account button | H8: User should successfully be redirected to Explore/home page | J8: Draft | L8: UR-02 | M8: Functional | N8: Ahmed Zahran
A9: TC_Registration_008 | B9: Verify registration feature in case of user entering first name that is less than minimum allowed character length | C9: Invalid | E9: User is already on registration page | F9: Enter first name in First name field | H9: Error message should appear below First name field "Name should be between 2 and 50 characters | J9: Draft | L9: UR-02 | M9: Functional | N9: Ahmed Zahran
A10: TC_Registration_009 | B10: Verify registration feature in case of user entering first name that is more than maximum allowed character length | C10: Invalid | E10: User is already on registration page | F10: Enter first name in First name field | H10: Error message should appear below First name field "Name should be between 2 and 50 characters | J10: Draft | L10: UR-02 | M10: Functional | N10: Ahmed Zahran
A11: TC_Registration_010 | B11: Verify registration feature in case of user entering Last name that is less than the minimum allowed character length | C11: Invalid | E11: User is already on registration page | F11: Enter last name in Last name field | H11: Error message should appear below First name field "Name should be between 2 and 50 characters | J11: Draft | L11: UR-02 | M11: Functional | N11: Ahmed Zahran
A12: TC_Registration_011 | B12: Verify registration feature in case of user entering Last name that is more than the maximum allowed character length | C12: Invalid | E12: User is already on registration page | F12: Enter last name in Last name field | H12: Error message should appear below First name field "Name should be between 2 and 50 characters | J12: Draft | L12: UR-02 | M12: Functional | N12: Ahmed Zahran
A13: TC_Registration_012 | B13: Verify registration feature in case of user entering a password that is less than minmum allowed character length | C13: Invalid | E13: User is already on registration page | F13: Enter password in Password field | H13: Error message should appear below password field "password cannot be less than 8 characters" | J13: Draft | L13: UR-03 | M13: Functional | N13: Ahmed Zahran
... A31: TC_Registration_030 | B31: Verify registration feature in case of user registering with empty Confirm password field | C31: Invalid | E31: User is already on registration page | F31: 1-Enter first name in First name field 2-Enter last name in Last field 3-Enter email in Email field 4-Enter password in Password field 5-Click on Create account button | H31: User should be prevented from registration and error message appears below Confirm password field " This field is required" | J31: Draft | L31: UR-01 | M31: Functional | N31: Ahmed Zahran
A33: TC_HomePage_01 | B33: The system shall redirect the user to the “Find Flights” Page when the user clicks on “Find Flights” in the navigation bar. | C33: valid | D33: Web App | E33: The User is logged in and is on the Home(Explore) Page | F33: =CONCATENATE("1- ",LEFT(E33,FIND(CHAR(160),SUBSTITUTE(E33," ",CHAR(160),2))),"Clicks",MID(E33,FIND(CHAR(160),SUBSTITUTE(E33," ",CHAR(160),7)) - 1 + 1,FIND(CHAR(160),SUBSTITUTE(E33," ",CHAR(160),9)) - (FIND(CHAR(160),SUBSTITUTE(E33," ",CHAR(160),7)) - 1)),CHAR(34),MID(B33,FIND(" “",B33) + 1 + 1,FIND("” ",B33) - 1 - (FIND(" “",B33) + 1)),CHAR(34)&" Butt",MID(E33,FIND(CHAR(160),SUBSTITUTE(E33," ",CHAR(160),7)) + 1,FIND(CHAR(160),SUBSTITUTE(E33," ",CHAR(160),8)) - (FIND(CHAR(160),SUBSTITUTE(E33," ",CHAR(160),7)))),MID(E33,FIND(CHAR(160),SUBSTITUTE(E33," ",CHAR(160),4)) + 1,FIND(CHAR(160),SUBSTITUTE(E33," ",CHAR(160),5)) - (FIND(CHAR(160),SUBSTITUTE(E33," ",CHAR(160),4)))),MID(E33,FIND(CHAR(160),SUBSTITUTE(E33," ",CHAR(160),8)) + 1,FIND(CHAR(160),SUBSTITUTE(E33," ",CHAR(160),9)) - (FIND(CHAR(160),SUBSTITUTE(E33," ",CHAR(160),8)))),"navigati",MID(E33,FIND(CHAR(160),SUBSTITUTE(E33," ",CHAR(160),7)) + 1,FIND(CHAR(160),SUBSTITUTE(E33," ",CHAR(160),8)) - (FIND(CHAR(160),SUBSTITUTE(E33," ",CHAR(160),7)))),"bar") -> 1- The User Clicks on the "Find Flights" Button in the navigation bar | G33: N/A | H33: 1- The user is redirected to the "Find Flights" Page to search for a flight | J33: Draft | M33: Functional | N33: Alaa
A34: TC_HomePage_02 | B34: The system shall redirect the user to the “My Bookings” Page when the user clicks on “My Bookings” in the navigation bar to show previous bookings. | C34: valid | D34: Web App | E34: The User is logged in and is on the Home(Explore) Page | F34: =CONCATENATE("1- ",LEFT(E34,FIND(CHAR(160),SUBSTITUTE(E34," ",CHAR(160),2))),"Clicks",MID(E34,FIND(CHAR(160),SUBSTITUTE(E34," ",CHAR(160),7)) - 1 + 1,FIND(CHAR(160),SUBSTITUTE(E34," ",CHAR(160),9)) - (FIND(CHAR(160),SUBSTITUTE(E34," ",CHAR(160),7)) - 1)),CHAR(34),MID(B34,FIND(" “",B34) + 1 + 1,FIND("” ",B34) - 1 - (FIND(" “",B34) + 1)),CHAR(34)&" Butt",MID(E34,FIND(CHAR(160),SUBSTITUTE(E34," ",CHAR(160),7)) + 1,FIND(CHAR(160),SUBSTITUTE(E34," ",CHAR(160),8)) - (FIND(CHAR(160),SUBSTITUTE(E34," ",CHAR(160),7)))),MID(E34,FIND(CHAR(160),SUBSTITUTE(E34," ",CHAR(160),4)) + 1,FIND(CHAR(160),SUBSTITUTE(E34," ",CHAR(160),5)) - (FIND(CHAR(160),SUBSTITUTE(E34," ",CHAR(160),4)))),MID(E34,FIND(CHAR(160),SUBSTITUTE(E34," ",CHAR(160),8)) + 1,FIND(CHAR(160),SUBSTITUTE(E34," ",CHAR(160),9)) - (FIND(CHAR(160),SUBSTITUTE(E34," ",CHAR(160),8)))),"navigati",MID(E34,FIND(CHAR(160),SUBSTITUTE(E34," ",CHAR(160),7)) + 1,FIND(CHAR(160),SUBSTITUTE(E34," ",CHAR(160),8)) - (FIND(CHAR(160),SUBSTITUTE(E34," ",CHAR(160),7)))),"bar") -> 1- The User Clicks on the "My Bookings" Button in the navigation bar | G34: N/A | H34: 1- The user is redirected to the "My Bookings" Page to show previous bookings | J34: Draft | M34: Functional | N34: Alaa
A35: TC_HomePage_03 | B35: The system shall stay on the same page when the user clicks on “Explore” in the navigation bar. | C35: valid | D35: Web App | E35: The User is logged in and is on the Home(Explore) Page | F35: =CONCATENATE("1- ",LEFT(E35,FIND(CHAR(160),SUBSTITUTE(E35," ",CHAR(160),2))),"Clicks",MID(E35,FIND(CHAR(160),SUBSTITUTE(E35," ",CHAR(160),7)) - 1 + 1,FIND(CHAR(160),SUBSTITUTE(E35," ",CHAR(160),9)) - (FIND(CHAR(160),SUBSTITUTE(E35," ",CHAR(160),7)) - 1)),CHAR(34),MID(B35,FIND(" “",B35) + 1 + 1,FIND("” ",B35) - 1 - (FIND(" “",B35) + 1)),CHAR(34)&" Butt",MID(E35,FIND(CHAR(160),SUBSTITUTE(E35," ",CHAR(160),7)) + 1,FIND(CHAR(160),SUBSTITUTE(E35," ",CHAR(160),8)) - (FIND(CHAR(160),SUBSTITUTE(E35," ",CHAR(160),7)))),MID(E35,FIND(CHAR(160),SUBSTITUTE(E35," ",CHAR(160),4)) + 1,FIND(CHAR(160),SUBSTITUTE(E35," ",CHAR(160),5)) - (FIND(CHAR(160),SUBSTITUTE(E35," ",CHAR(160),4)))),MID(E35,FIND(CHAR(160),SUBSTITUTE(E35," ",CHAR(160),8)) + 1,FIND(CHAR(160),SUBSTITUTE(E35," ",CHAR(160),9)) - (FIND(CHAR(160),SUBSTITUTE(E35," ",CHAR(160),8)))),"navigati",MID(E35,FIND(CHAR(160),SUBSTITUTE(E35," ",CHAR(160),7)) + 1,FIND(CHAR(160),SUBSTITUTE(E35," ",CHAR(160),8)) - (FIND(CHAR(160),SUBSTITUTE(E35," ",CHAR(160),7)))),"bar") -> 1- The User Clicks on the "Explore" Button in the navigation bar | G35: N/A | H35: 1- The user stays on the same page | J35: Draft | M35: Functional | N35: Alaa
A36: TC_HomePage_04 | B36: The system shall redirect the user to the “Login” Page when the user clicks on “LOGOUT” in the navigation bar to login again. | C36: valid | D36: Web App | E36: The User is logged in and is on the Home(Explore) Page | F36: =CONCATENATE("1- ",LEFT(E36,FIND(CHAR(160),SUBSTITUTE(E36," ",CHAR(160),2))),"Clicks",MID(E36,FIND(CHAR(160),SUBSTITUTE(E36," ",CHAR(160),7)) - 1 + 1,FIND(CHAR(160),SUBSTITUTE(E36," ",CHAR(160),9)) - (FIND(CHAR(160),SUBSTITUTE(E36," ",CHAR(160),7)) - 1)),CHAR(34),MID(B36,FIND(" “",B36) + 1 + 1,FIND("” ",B36) - 1 - (FIND(" “",B36) + 1)),CHAR(34)&" Butt",MID(E36,FIND(CHAR(160),SUBSTITUTE(E36," ",CHAR(160),7)) + 1,FIND(CHAR(160),SUBSTITUTE(E36," ",CHAR(160),8)) - (FIND(CHAR(160),SUBSTITUTE(E36," ",CHAR(160),7)))),MID(E36,FIND(CHAR(160),SUBSTITUTE(E36," ",CHAR(160),4)) + 1,FIND(CHAR(160),SUBSTITUTE(E36," ",CHAR(160),5)) - (FIND(CHAR(160),SUBSTITUTE(E36," ",CHAR(160),4)))),MID(E36,FIND(CHAR(160),SUBSTITUTE(E36," ",CHAR(160),8)) + 1,FIND(CHAR(160),SUBSTITUTE(E36," ",CHAR(160),9)) - (FIND(CHAR(160),SUBSTITUTE(E36," ",CHAR(160),8)))),"navigati",MID(E36,FIND(CHAR(160),SUBSTITUTE(E36," ",CHAR(160),7)) + 1,FIND(CHAR(160),SUBSTITUTE(E36," ",CHAR(160),8)) - (FIND(CHAR(160),SUBSTITUTE(E36," ",CHAR(160),7)))),"bar") -> 1- The User Clicks on the "Login" Button in the navigation bar | G36: N/A | H36: 1- The user is redirected to the "login" Page and asked to login again | J36: Draft | M36: Functional | N36: Alaa
A37: TC_HomePage_05 | B37: The system shall show 9 tour cards of Italy when clicking “Italy”, showing tour rating, cost, and “View Tour” button to show tour details. | C37: valid | D37: Web App | E37: The User is logged in and is on the Home(Explore) Page | F37: 1- The user clicks on "Italy" button | G37: N/A | H37: 1- The system shows 9 tour cards of top destinations in Italy | J37: Draft | M37: Functional | N37: Alaa | O37: Feels Like UI
A38: TC_HomePage_06 | B38: The system shall show 9 tour cards of France when clicking “France”, showing tour rating, cost, and “View Tour” button to show tour details. | C38: valid | D38: Web App | E38: The User is logged in and is on the Home(Explore) Page | F38: 1- The user clicks on "France" button | G38: N/A | H38: 1- The system shows 9 tour cards of top destinations in France | J38: Draft | M38: Functional | N38: Alaa | O38: Feels Like UI
A39: TC_HomePage_07 | B39: The system shall show 9 tour cards of Egypt when clicking “Egypt”, showing tour rating, cost, and “View Tour” button to show tour details. | C39: valid | D39: Web App | E39: The User is logged in and is on the Home(Explore) Page | F39: 1- The user clicks on "Egypt" button | G39: N/A | H39: 1- The system shows 9 tour cards of top destinations in Egypt | J39: Draft | M39: Functional | N39: Alaa | O39: Feels Like UI
A40: TC_HomePage_08 | B40: The system shall redirect the user to the corresponding Destination Details Page when the user clicks on “View Tour” in any tour card. | C40: valid | D40: Web App | E40: The User is logged in and is on the Home(Explore) Page | F40: 1- The User Clicks on "View Tour" Button in any tour card. | G40: N/A | H40: 1- The user is redirected to the corresponding Destination Details Page | J40: Draft | M40: Functional | N40: Alaa
A42: TC_DestinationDetails_01 | B42: The system shall allow the user to proceed to the booking flow by clicking the “Book Flight” button. | C42: valid | D42: Web App | E42: The User is logged in and is on the Home(Explore) Page and is on the destination details page after clicking "view tour" on any card | F42: 1- The User Clicks "Book Flight". | G42: N/A | H42: 1- The user is redirected to the "Find Flights" Page with the Destination Field set to the re-booked destination | J42: Draft | M42: Functional | N42: Alaa
A44: TC-PassangerDetails-01 | B44: Verify submission of valid passenger details | C44: valid | D44: Web App | E44: User on Passenger Details page | F44: Enter all valid data | G44: Ahmed Ali / A1234567 / 10-10-2000 | H44: Data accepted and stored temporarily | I44: Data saved | L44: PD-01,PD-06 | M44: Functional | N44: Abdelrahman khaled
A45: TC-PassangerDetails-02 | B45: Validate required Full Name field when left empty | C45: Invalid | D45: Web App | E45: User on Passenger Details page | F45: Leave Full Name empty | G45: "" / A1234567 / 10-10-2000 | H45: Error “This field is required” under Full Name | I45: No data saved | L45: PD-02,PD-05 | M45: Functional | N45: Abdelrahman khaled
A46: TC-PassangerDetails-03 | B46: Validate required Passport Number field when left empty | C46: Invalid | D46: Web App | E46: User on Passenger Details page | F46: Leave Passport empty | G46: Ahmed Ali / "" / 10-10-2000 | H46: Error message displayed under Passport | I46: No data saved | L46: PD-03,PD-05 | M46: Functional | N46: Abdelrahman khaled
A47: TC-PassangerDetails-04 | B47: Validate required Date of Birth field when left empty | C47: Invalid | D47: Web App | E47: User on Passenger Details page | F47: Leave DOB empty | G47: Ahmed Ali / A1234567 / "" | H47: Error message displayed under DOB | I47: No data saved | L47: PD-04,PD-05 | M47: Functional | N47: Abdelrahman khaled
A48: TC-PassangerDetails-05 | B48: Validate Full Name rejects numeric characters | C48: Invalid | D48: Web App | E48: User on Passenger Details page | F48: Enter invalid name | G48: Ahmed123 | H48: Error message displayed | I48: No data saved | L48: PD-07,PD-08 | M48: Functional | N48: Abdelrahman khaled
A49: TC-PassangerDetails-06 | B49: Validate Full Name rejects special characters | C49: Invalid | D49: Web App | E49: User on Passenger Details page | F49: Enter invalid name | G49: Ahmed@Ali | H49: Error message displayed | I49: No data saved | L49: PD-07,PD-08 | M49: Functional | N49: Abdelrahman khaled
A50: TC-PassangerDetails-07 | B50: Validate Full Name minimum length constraint (less than 3 characters) | C50: Invalid | D50: Web App | E50: User on Passenger Details page | F50: Enter short name | G50: Ah | H50: Error message displayed | I50: No data saved | L50: PD-09 | M50: Functional | N50: Abdelrahman khaled
A51: TC-PassangerDetails-08 | B51: Validate Full Name maximum length constraint (more than 30 characters) | C51: Invalid | D51: Web App | E51: User on Passenger Details page | F51: Enter long name | G51: 31+ chararacters | H51: Error message displayed | I51: No data saved | L51: PD-09 | M51: Functional | N51: Abdelrahman khaled
A52: TC-PassangerDetails-09 | B52: Validate Passport Number rejects special characters | C52: Invalid | D52: Web App | E52: User on Passenger Details page | F52: Enter invalid passport | G52: A12@456 | H52: Error message displayed | I52: No data saved | L52: PD-10 | M52: Functional | N52: Abdelrahman khaled
A53: TC-PassangerDetails-10 | B53: Validate Passport Number rejects spaces | C53: Invalid | D53: Web App | E53: User on Passenger Details page | F53: Enter passport with space | G53: A12 3456 | H53: Error message displayed | I53: No data saved | L53: PD-11 | M53: Functional | N53: Abdelrahman khaled
A54: TC-PassangerDetails-11 | B54: Validate Date of Birth does not accept future dates | C54: Invalid | D54: Web App | E54: User on Passenger Details page | F54: Enter future DOB | G54: 54789 | H54: Error message displayed | I54: No data saved | L54: PD-12 | M54: Functional | N54: Abdelrahman khaled
A56: TC-Payment-01 | B56: Verify successful payment with valid card details | C56: valid | D56: Web App | E56: User on Payment page | F56: 1-Enter valid data in all fields 2-Click Pay & Confirm | G56: 4111111111111111 / Ahmed Ali / 12/26 / 123 | H56: Payment processed successfully | I56: Redirect to Share Experience page with popup | L56: PAY-01 | M56: Functional | N56: Abdelrahman khaled
A57: TC-Payment-02 | B57: Validate empty Card Number field on payment submission | C57: Invalid | D57: Web App | E57: User on Payment page | F57: 1-Leave Card Number empty 2-Click Pay & Confirm | G57: ""/ Ahmed Ali / 12/26 / 123 | H57: Error “This field is required” shown | I57: No payment | L57: PAY-02,PAY-07 | M57: Functional | N57: Abdelrahman khaled
A58: TC-Payment-03 | B58: Validate empty Cardholder Name field on payment submission | C58: Invalid | D58: Web App | E58: User on Payment page | F58: 1-Leave Name empty 2-Click Pay & Confirm | G58: Empty Name | H58: Error “This field is required” shown | I58: No payment | L58: PAY-03,PAY-07 | M58: Functional | N58: Abdelrahman khaled
A59: TC-Payment-04 | B59: Validate empty Expiry Date field on payment submission | C59: Invalid | D59: Web App | E59: User on Payment page | F59: 1-Leave Expiry empty 2-Click Pay & Confirm | G59: Empty Expiry | H59: Error “This field is required” shown | I59: No payment | L59: PAY-04,PAY-07 | M59: Functional | N59: Abdelrahman khaled
A60: TC-Payment-05 | B60: Validate empty CVV field on payment submission | C60: Invalid | D60: Web App | E60: User on Payment page | F60: 1-Leave CVV empty 2-Click Pay & Confirm | G60: Empty CVV | H60: Error “This field is required” shown | I60: No payment | L60: PAY-05,PAY-07 | M60: Functional | N60: Abdelrahman khaled
A61: TC-Payment-06 | B61: Verify payment processing is triggered on Pay & Confirm button click | C61: valid | D61: Web App | E61: All fields filled | F61: Click Pay & Confirm | G61: Valid data | H61: Payment process starts | I61: Redirect to Share Experience page | L61: PAY-06 | M61: Functional | N61: Abdelrahman khaled
...

Sheet Test Execution 
A1: TesTCASE ID | B1: execution status | C1: Test Cases Title | D1: valid/invaldid | E1: Environment | F1: Pre-condition | G1: Steps | H1: Test Data | I1: Expected Results | J1: Actual result | K1: Post Condition | L1: TC Status | M1: Attachment | N1: Requirement ID | O1: Type | P1: Tester | Q1: Comment
A2: TC_Registration_001 | C2: Verify registration feature in case of user registering with valid data for all fields | D2: valid | F2: User is already on registration page | G2: 1-Enter first name in First name field 2-Enter last name in Last name field 3-Enter email in Email field 4-Enter password in password field 5-Enter confirm password in Confirm password field 6-Click on Create account button | I2: User should successfully be redirected to Explore/home page | L2: Draft | N2: UR-09 | O2: Functional | P2: Ahmed Zahran
A3: TC_Registration_002 | C3: Verify registration feature in case of user clicking on login link | D3: valid | F3: User is already on registration page | G3: 1-Navigate to login link 2- Click on login link | I3: User should successfully be redirected to Login page | L3: Draft | N3: UR-10 | O3: Functional | P3: Ahmed Zahran
A4: TC_Registration_003 | C4: Verify registration feature in case of user entering First name that is exactly the minimum allowed character length | D4: valid | F4: User is already on registration page | G4: 1-Enter first name in First name field 2-Enter last name in Last name field 3-Enter email in Email field 4-Enter password in password field 5-Enter confirm password in Confirm password field 6-Click on Create account button | I4: User should successfully be redirected to Explore/home page | L4: Draft | N4: UR-02 | O4: Functional | P4: Ahmed Zahran
A5: TC_Registration_004 | C5: Verify registration feature in case of user entering First name that is exactly the maximim allowed character length | D5: valid | F5: User is already on registration page | G5: 1-Enter first name in First name field 2-Enter last name in Last name field 3-Enter email in Email field 4-Enter password in password field 5-Enter confirm password in Confirm password field 6-Click on Create account button | I5: User should successfully be redirected to Explore/home page | L5: Draft | N5: UR-02 | O5: Functional | P5: Ahmed Zahran
A6: TC_Registration_005 | C6: Verify registration feature in case of user entering Last name that is exactly the minimum allowed character length | D6: valid | F6: User is already on registration page | G6: 1-Enter first name in First name field 2-Enter last name in Last name field 3-Enter email in Email field 4-Enter password in password field 5-Enter confirm password in Confirm password field 6-Click on Create account button | I6: User should successfully be redirected to Explore/home page | L6: Draft | N6: UR-02 | O6: Functional | P6: Ahmed Zahran
A7: TC_Registration_006 | C7: Verify registration feature in case of user entering Last name that is exactly the maxiimum allowed character length | D7: valid | F7: User is already on registration page | G7: "1-Enter first name in First name field 2-Enter last name in Last name field 3-Enter email in Email field 4-Enter password in password field 5-Enter confirm password in Confirm password field 6-Click on Create account button" | I7: User should successfully be redirected to Explore/home page | L7: Draft | N7: UR-02 | O7: Functional | P7: Ahmed Zahran
A8: TC_Registration_007 | C8: Verfiy registration feature in case of user entering password that is exactly the minimum allowed character length | D8: valid | F8: User is already on registration page | G8: 1-Enter first name in First name field 2-Enter last name in Last name field 3-Enter email in Email field 4-Enter password in password field 5-Enter confirm password in Confirm password field 6-Click on Create account button | I8: User should successfully be redirected to Explore/home page | L8: Draft | N8: UR-02 | O8: Functional | P8: Ahmed Zahran
A9: TC_Registration_008 | C9: Verify registration feature in case of user entering first name that is less than minimum allowed character length | D9: Invalid | F9: User is already on registration page | G9: Enter first name in First name field | I9: Error message should appear below First name field "Name should be between 2 and 50 characters | L9: Draft | N9: UR-02 | O9: Functional | P9: Ahmed Zahran
A10: TC_Registration_009 | C10: Verify registration feature in case of user entering first name that is more than maximum allowed character length | D10: Invalid | F10: User is already on registration page | G10: Enter first name in First name field | I10: Error message should appear below First name field "Name should be between 2 and 50 characters | L10: Draft | N10: UR-02 | O10: Functional | P10: Ahmed Zahran
A11: TC_Registration_010 | C11: Verify registration feature in case of user entering Last name that is less than the minimum allowed character length | D11: Invalid | F11: User is already on registration page | G11: Enter last name in Last name field | I11: Error message should appear below First name field "Name should be between 2 and 50 characters | L11: Draft | N11: UR-02 | O11: Functional | P11: Ahmed Zahran
A12: TC_Registration_011 | C12: Verify registration feature in case of user entering Last name that is more than the maximum allowed character length | D12: Invalid | F12: User is already on registration page | G12: Enter last name in Last name field | I12: Error message should appear below First name field "Name should be between 2 and 50 characters | L12: Draft | N12: UR-02 | O12: Functional | P12: Ahmed Zahran
A13: TC_Registration_012 | C13: Verify registration feature in case of user entering a password that is less than minmum allowed character length | D13: Invalid | F13: User is already on registration page | G13: Enter password in Password field | I13: Error message should appear below password field "password cannot be less than 8 characters" | L13: Draft | N13: UR-03 | O13: Functional | P13: Ahmed Zahran
... A31: TC_Registration_030 | C31: Verify registration feature in case of user registering with empty Confirm password field | D31: Invalid | F31: User is already on registration page | G31: 1-Enter first name in First name field 2-Enter last name in Last field 3-Enter email in Email field 4-Enter password in Password field 5-Click on Create account button | I31: User should be prevented from registration and error message appears below Confirm password field " This field is required" | L31: Draft | N31: UR-01 | O31: Functional | P31: Ahmed Zahran
L32: Draft
A33: TC_HomePage_01 | C33: The system shall redirect the user to the “Find Flights” Page when the user clicks on “Find Flights” in the navigation bar. | D33: valid | F33: The User is logged in and is on the Home(Explore) Page | G33: =CONCATENATE("1- ",LEFT(F33,FIND(CHAR(160),SUBSTITUTE(F33," ",CHAR(160),2))),"Clicks",MID(F33,FIND(CHAR(160),SUBSTITUTE(F33," ",CHAR(160),7)) - 1 + 1,FIND(CHAR(160),SUBSTITUTE(F33," ",CHAR(160),9)) - (FIND(CHAR(160),SUBSTITUTE(F33," ",CHAR(160),7)) - 1)),CHAR(34),MID(C33,FIND(" “",C33) + 1 + 1,FIND("” ",C33) - 1 - (FIND(" “",C33) + 1)),CHAR(34)&" Butt",MID(F33,FIND(CHAR(160),SUBSTITUTE(F33," ",CHAR(160),7)) + 1,FIND(CHAR(160),SUBSTITUTE(F33," ",CHAR(160),8)) - (FIND(CHAR(160),SUBSTITUTE(F33," ",CHAR(160),7)))),MID(F33,FIND(CHAR(160),SUBSTITUTE(F33," ",CHAR(160),4)) + 1,FIND(CHAR(160),SUBSTITUTE(F33," ",CHAR(160),5)) - (FIND(CHAR(160),SUBSTITUTE(F33," ",CHAR(160),4)))),MID(F33,FIND(CHAR(160),SUBSTITUTE(F33," ",CHAR(160),8)) + 1,FIND(CHAR(160),SUBSTITUTE(F33," ",CHAR(160),9)) - (FIND(CHAR(160),SUBSTITUTE(F33," ",CHAR(160),8)))),"navigati",MID(F33,FIND(CHAR(160),SUBSTITUTE(F33," ",CHAR(160),7)) + 1,FIND(CHAR(160),SUBSTITUTE(F33," ",CHAR(160),8)) - (FIND(CHAR(160),SUBSTITUTE(F33," ",CHAR(160),7)))),"bar") -> 1- The User Clicks on the "Find Flights" Button in the navigation bar | I33: 1- The user is redirected to the "Find Flights" Page to search for a flight | L33: Draft | O33: Functional | P33: Alaa
A34: TC_HomePage_02 | C34: The system shall redirect the user to the “My Bookings” Page when the user clicks on “My Bookings” in the navigation bar to show previous bookings. | D34: valid | F34: The User is logged in and is on the Home(Explore) Page | G34: =CONCATENATE("1- ",LEFT(F34,FIND(CHAR(160),SUBSTITUTE(F34," ",CHAR(160),2))),"Clicks",MID(F34,FIND(CHAR(160),SUBSTITUTE(F34," ",CHAR(160),7)) - 1 + 1,FIND(CHAR(160),SUBSTITUTE(F34," ",CHAR(160),9)) - (FIND(CHAR(160),SUBSTITUTE(F34," ",CHAR(160),7)) - 1)),CHAR(34),MID(C34,FIND(" “",C34) + 1 + 1,FIND("” ",C34) - 1 - (FIND(" “",C34) + 1)),CHAR(34)&" Butt",MID(F34,FIND(CHAR(160),SUBSTITUTE(F34," ",CHAR(160),7)) + 1,FIND(CHAR(160),SUBSTITUTE(F34," ",CHAR(160),8)) - (FIND(CHAR(160),SUBSTITUTE(F34," ",CHAR(160),7)))),MID(F34,FIND(CHAR(160),SUBSTITUTE(F34," ",CHAR(160),4)) + 1,FIND(CHAR(160),SUBSTITUTE(F34," ",CHAR(160),5)) - (FIND(CHAR(160),SUBSTITUTE(F34," ",CHAR(160),4)))),MID(F34,FIND(CHAR(160),SUBSTITUTE(F34," ",CHAR(160),8)) + 1,FIND(CHAR(160),SUBSTITUTE(F34," ",CHAR(160),9)) - (FIND(CHAR(160),SUBSTITUTE(F34," ",CHAR(160),8)))),"navigati",MID(F34,FIND(CHAR(160),SUBSTITUTE(F34," ",CHAR(160),7)) + 1,FIND(CHAR(160),SUBSTITUTE(F34," ",CHAR(160),8)) - (FIND(CHAR(160),SUBSTITUTE(F34," ",CHAR(160),7)))),"bar") -> 1- The User Clicks on the "My Bookings" Button in the navigation bar | I34: 1- The user is redirected to the "My Bookings" Page to show previous bookings | L34: Draft | O34: Functional | P34: Alaa
A35: TC_HomePage_03 | C35: The system shall stay on the same page when the user clicks on “Explore” in the navigation bar. | D35: valid | F35: The User is logged in and is on the Home(Explore) Page | G35: =CONCATENATE("1- ",LEFT(F35,FIND(CHAR(160),SUBSTITUTE(F35," ",CHAR(160),2))),"Clicks",MID(F35,FIND(CHAR(160),SUBSTITUTE(F35," ",CHAR(160),7)) - 1 + 1,FIND(CHAR(160),SUBSTITUTE(F35," ",CHAR(160),9)) - (FIND(CHAR(160),SUBSTITUTE(F35," ",CHAR(160),7)) - 1)),CHAR(34),MID(C35,FIND(" “",C35) + 1 + 1,FIND("” ",C35) - 1 - (FIND(" “",C35) + 1)),CHAR(34)&" Butt",MID(F35,FIND(CHAR(160),SUBSTITUTE(F35," ",CHAR(160),7)) + 1,FIND(CHAR(160),SUBSTITUTE(F35," ",CHAR(160),8)) - (FIND(CHAR(160),SUBSTITUTE(F35," ",CHAR(160),7)))),MID(F35,FIND(CHAR(160),SUBSTITUTE(F35," ",CHAR(160),4)) + 1,FIND(CHAR(160),SUBSTITUTE(F35," ",CHAR(160),5)) - (FIND(CHAR(160),SUBSTITUTE(F35," ",CHAR(160),4)))),MID(F35,FIND(CHAR(160),SUBSTITUTE(F35," ",CHAR(160),8)) + 1,FIND(CHAR(160),SUBSTITUTE(F35," ",CHAR(160),9)) - (FIND(CHAR(160),SUBSTITUTE(F35," ",CHAR(160),8)))),"navigati",MID(F35,FIND(CHAR(160),SUBSTITUTE(F35," ",CHAR(160),7)) + 1,FIND(CHAR(160),SUBSTITUTE(F35," ",CHAR(160),8)) - (FIND(CHAR(160),SUBSTITUTE(F35," ",CHAR(160),7)))),"bar") -> 1- The User Clicks on the "Explore" Button in the navigation bar | I35: 1- The user stays on the same page | L35: Draft | O35: Functional | P35: Alaa
A36: TC_HomePage_04 | C36: The system shall redirect the user to the “Login” Page when the user clicks on “LOGOUT” in the navigation bar to login again. | D36: valid | F36: The User is logged in and is on the Home(Explore) Page | G36: =CONCATENATE("1- ",LEFT(F36,FIND(CHAR(160),SUBSTITUTE(F36," ",CHAR(160),2))),"Clicks",MID(F36,FIND(CHAR(160),SUBSTITUTE(F36," ",CHAR(160),7)) - 1 + 1,FIND(CHAR(160),SUBSTITUTE(F36," ",CHAR(160),9)) - (FIND(CHAR(160),SUBSTITUTE(F36," ",CHAR(160),7)) - 1)),CHAR(34),MID(C36,FIND(" “",C36) + 1 + 1,FIND("” ",C36) - 1 - (FIND(" “",C36) + 1)),CHAR(34)&" Butt",MID(F36,FIND(CHAR(160),SUBSTITUTE(F36," ",CHAR(160),7)) + 1,FIND(CHAR(160),SUBSTITUTE(F36," ",CHAR(160),8)) - (FIND(CHAR(160),SUBSTITUTE(F36," ",CHAR(160),7)))),MID(F36,FIND(CHAR(160),SUBSTITUTE(F36," ",CHAR(160),4)) + 1,FIND(CHAR(160),SUBSTITUTE(F36," ",CHAR(160),5)) - (FIND(CHAR(160),SUBSTITUTE(F36," ",CHAR(160),4)))),MID(F36,FIND(CHAR(160),SUBSTITUTE(F36," ",CHAR(160),8)) + 1,FIND(CHAR(160),SUBSTITUTE(F36," ",CHAR(160),9)) - (FIND(CHAR(160),SUBSTITUTE(F36," ",CHAR(160),8)))),"navigati",MID(F36,FIND(CHAR(160),SUBSTITUTE(F36," ",CHAR(160),7)) + 1,FIND(CHAR(160),SUBSTITUTE(F36," ",CHAR(160),8)) - (FIND(CHAR(160),SUBSTITUTE(F36," ",CHAR(160),7)))),"bar") -> 1- The User Clicks on the "Login" Button in the navigation bar | I36: 1- The user is redirected to the "login" Page and asked to login again | L36: Draft | O36: Functional | P36: Alaa
A37: TC_HomePage_05 | C37: The system shall show 9 tour cards of Italy when clicking “Italy”, showing tour rating, cost, and “View Tour” button to show tour details. | D37: valid | F37: The User is logged in and is on the Home(Explore) Page | G37: 1- The user clicks on "Italy" button | I37: 1- The system shows 9 tour cards of top destinations in Italy | L37: Draft | O37: Functional | P37: Alaa
A38: TC_HomePage_06 | C38: The system shall show 9 tour cards of France when clicking “France”, showing tour rating, cost, and “View Tour” button to show tour details. | D38: valid | F38: The User is logged in and is on the Home(Explore) Page | G38: 1- The user clicks on "France" button | I38: 1- The system shows 9 tour cards of top destinations in France | L38: Draft | O38: Functional | P38: Alaa
A39: TC_HomePage_07 | C39: The system shall show 9 tour cards of Egypt when clicking “Egypt”, showing tour rating, cost, and “View Tour” button to show tour details. | D39: valid | F39: The User is logged in and is on the Home(Explore) Page | G39: 1- The user clicks on "Egypt" button | I39: 1- The system shows 9 tour cards of top destinations in Egypt | L39: Draft | O39: Functional | P39: Alaa
A40: TC_HomePage_08 | C40: The system shall redirect the user to the corresponding Destination Details Page when the user clicks on “View Tour” in any tour card. | D40: valid | F40: The User is logged in and is on the Home(Explore) Page | G40: 1- The User Clicks on "View Tour" Button in any tour card. | I40: 1- The user is redirected to the corresponding Destination Details Page | L40: Draft | O40: Functional | P40: Alaa
L41: Draft
A42: TC_DestinationDetails_01 | C42: The system shall allow the user to proceed to the booking flow by clicking the “Book Flight” button. | D42: valid | F42: The User is logged in and is on the Home(Explore) Page and is on the destination details page after clicking "view tour" on any card | G42: 1- The User Clicks "Book Flight". | I42: 1- The user is redirected to the "Find Flights" Page with the Destination Field set to the re-booked destination | L42: Draft | O42: Functional | P42: Alaa
L43: Draft
A44: TC-PassangerDetails-01 | C44: Verify submission of valid passenger details | D44: valid | F44: User on Passenger Details page | G44: Enter all valid data | I44: Data accepted and stored temporarily | L44: Draft | N44: PD-01,PD-06 | O44: Functional | P44: Abdelrahman khaled
A45: TC-PassangerDetails-02 | C45: Validate required Full Name field when left empty | D45: Invalid | F45: User on Passenger Details page | G45: Leave Full Name empty | I45: Error “This field is required” under Full Name | L45: Draft | N45: PD-02,PD-05 | O45: Functional | P45: Abdelrahman khaled
A46: TC-PassangerDetails-03 | C46: Validate required Passport Number field when left empty | D46: Invalid | F46: User on Passenger Details page | G46: Leave Passport empty | I46: Error message displayed under Passport | L46: Draft | N46: PD-03,PD-05 | O46: Functional | P46: Abdelrahman khaled
A47: TC-PassangerDetails-04 | C47: Validate required Date of Birth field when left empty | D47: Invalid | F47: User on Passenger Details page | G47: Leave DOB empty | I47: Error message displayed under DOB | L47: Draft | N47: PD-04,PD-05 | O47: Functional | P47: Abdelrahman khaled
A48: TC-PassangerDetails-05 | C48: Validate Full Name rejects numeric characters | D48: Invalid | F48: User on Passenger Details page | G48: Enter invalid name | I48: Error message displayed | L48: Draft | N48: PD-07,PD-08 | O48: Functional | P48: Abdelrahman khaled
A49: TC-PassangerDetails-06 | C49: Validate Full Name rejects special characters | D49: Invalid | F49: User on Passenger Details page | G49: Enter invalid name | I49: Error message displayed | L49: Draft | N49: PD-07,PD-08 | O49: Functional | P49: Abdelrahman khaled
A50: TC-PassangerDetails-07 | C50: Validate Full Name minimum length constraint (less than 3 characters) | D50: Invalid | F50: User on Passenger Details page | G50: Enter short name | I50: Error message displayed | L50: Draft | N50: PD-09 | O50: Functional | P50: Abdelrahman khaled
A51: TC-PassangerDetails-08 | C51: Validate Full Name maximum length constraint (more than 30 characters) | D51: Invalid | F51: User on Passenger Details page | G51: Enter long name | I51: Error message displayed | L51: Draft | N51: PD-09 | O51: Functional | P51: Abdelrahman khaled
A52: TC-PassangerDetails-09 | C52: Validate Passport Number rejects special characters | D52: Invalid | F52: User on Passenger Details page | G52: Enter invalid passport | I52: Error message displayed | L52: Draft | N52: PD-10 | O52: Functional | P52: Abdelrahman khaled
A53: TC-PassangerDetails-10 | C53: Validate Passport Number rejects spaces | D53: Invalid | F53: User on Passenger Details page | G53: Enter passport with space | I53: Error message displayed | L53: Draft | N53: PD-11 | O53: Functional | P53: Abdelrahman khaled
A54: TC-PassangerDetails-11 | C54: Validate Date of Birth does not accept future dates | D54: Invalid | F54: User on Passenger Details page | G54: Enter future DOB | I54: Error message displayed | L54: Draft | N54: PD-12 | O54: Functional | P54: Abdelrahman khaled
L55: Draft
A56: TC-Payment-01 | C56: Verify successful payment with valid card details | D56: valid | F56: User on Payment page | G56: 1-Enter valid data in all fields 2-Click Pay & Confirm | I56: Payment processed successfully | L56: Draft | N56: PAY-01 | O56: Functional | P56: Abdelrahman khaled
A57: TC-Payment-02 | C57: Validate empty Card Number field on payment submission | D57: Invalid | F57: User on Payment page | G57: 1-Leave Card Number empty 2-Click Pay & Confirm | I57: Error “This field is required” shown | L57: Draft | N57: PAY-02,PAY-07 | O57: Functional | P57: Abdelrahman khaled
...

Sheet Bug Reports
A1: Defect_ID | B1: Defect Title/Issue | C1: Pre-condition | D1: Test Data | E1: (Test-Steps)procedures | F1: Expected Result | G1: Actual Result | H1: Attachment | I1: Priority | J1: Probability | K1: Severity | L1: Bug Type | M1: Categorization | N1: Test case ID | O1: Defect Status | Q1: Req ID | R1: Created by

Sheet RTM
A1: Feature | B1: SIQ | C1: SRS | D1: TC
A2: Login | B2: SIQ-2 | C2: UL-01 | D2: {=IFERROR(TEXTJOIN(CHAR(10), TRUE, IF(ISNUMBER(SEARCH(C2, 'Test Cases'!$L$2:$L$477)), 'Test Cases'!$A$2:$A$477, "")), "")} -> TC_Login_004 TC_Login_005
B3: SIQ-5 | C3: UL-02 | D3: {=IFERROR(TEXTJOIN(CHAR(10), TRUE, IF(ISNUMBER(SEARCH(C3, 'Test Cases'!$L$2:$L$477)), 'Test Cases'!$A$2:$A$477, "")), "")} -> TC_Login_006 TC_Login_007 TC_Login_008
B4: SIQ-4 | C4: UL-03 | D4: {=IFERROR(TEXTJOIN(CHAR(10), TRUE, IF(ISNUMBER(SEARCH(C4, 'Test Cases'!$L$2:$L$477)), 'Test Cases'!$A$2:$A$477, "")), "")} -> TC_Login_009
B5: SIQ-6 | C5: UL-04 | D5: {=IFERROR(TEXTJOIN(CHAR(10), TRUE, IF(ISNUMBER(SEARCH(C5, 'Test Cases'!$L$2:$L$477)), 'Test Cases'!$A$2:$A$477, "")), "")} -> TC_Login_003
B6: SIQ-7 SIQ-8 | C6: UL-05 | D6: {=IFERROR(TEXTJOIN(CHAR(10), TRUE, IF(ISNUMBER(SEARCH(C6, 'Test Cases'!$L$2:$L$477)), 'Test Cases'!$A$2:$A$477, "")), "")} -> TC_Login_002
B7: SIQ-3 | C7: UL-06 | D7: {=IFERROR(TEXTJOIN(CHAR(10), TRUE, IF(ISNUMBER(SEARCH(C7, 'Test Cases'!$L$2:$L$477)), 'Test Cases'!$A$2:$A$477, "")), "")} -> TC_Login_001
A9: Register | B9: SIQ-11 | C9: UR-01 | D9: TC_Registration_026 TC_Registration_027 TC_Registration_028 TC_Registration_029 TC_Registration_030
B10: SIQ-12 | C10: UR-02 | D10: TC_Registration_003 TC_Registration_004 TC_Registration_005 TC_Registration_006 TC_Registration_007 TC_Registration_008 TC_Registration_009 TC_Registration_010 TC_Registration_011
B11: SIQ-15 | C11: UR-03 | D11: TC_Registration_012
B12: SIQ-14 | C12: UR-04 | D12: TC_Registration_013 TC_Registration_014 TC_Registration_015 TC_Registration_016
B13: SIQ-16 | C13: UR-05 | D13: TC_Registration_017
B14: SIQ-17 | C14: UR-06 | D14: TC_Registration_018 TC_Registration_019 TC_Registration_020
B15: SIQ-18 | C15: UR-07 | D15: TC_Registration_021 TC_Registration_022 TC_Registration_023 TC_Registration_024
B16: SIQ-20 | C16: UR-08 | D16: TC_Registration_025
B17: SIQ-19 | C17: UR-09 | D17: TC_Registration_001
B18: SIQ-21 | C18: UR-10 | D18: TC_Registration_002
A20: Home Page | B20: SIQ-20 | C20: HP-01 | D20: TC_HomePage_01
B21: SIQ-20 | C21: HP-02 | D21: TC_HomePage_02
B22: SIQ-20 | C22: HP-03 | D22: TC_HomePage_03
B23: SIQ-21 | C23: HP-04 | D23: TC_HomePage_04
B24: SIQ-20 | C24: HP-05 | D24: TC_HomePage_05
B25: SIQ-20 | C25: HP-06 | D25: TC_HomePage_06
B26: SIQ-20 | C26: HP-07 | D26: TC_HomePage_07
B27: SIQ-20 | C27: HP-08 | D27: TC_HomePage_08
A29: Destination Details | B29: SIQ-23 | C29: DD-01 | D29: TC_DestinationDetails_01
A31: Flight Search | B31: REQ_5 | C31: FS-01 | D31: TC_FlightSearch_001, TC_FlightSearch_002, TC_FlightSearch_003
C32: FS-02 | D32: TC_FlightSearch_001, TC_FlightSearch_004, TC_FlightSearch_005
C33: FS-03 | D33: TC_FlightSearch_006
C34: FS-04 | D34: TC_FlightSearch_007
C35: FS-05 | D35: TC_FlightSearch_008
C36: FS-06 | D36: TC_FlightSearch_009
C37: FS-07 | D37: TC_FlightSearch_001, TC_FlightSearch_010
C38: FS-08 | D38: TC_FlightSearch_011, TC_FlightSearch_013
C39: FS-09 | D39: TC_FlightSearch_012, TC_FlightSearch_013
C40: FS-10 | D40: TC_FlightSearch_001, TC_FlightSearch_014, TC_FlightSearch_015
C41: FS-11 | D41: TC_FlightSearch_016, TC_FlightSearch_017, TC_FlightSearch_018
C42: FS-12 | D42: TC_FlightSearch_019, TC_FlightSearch_020
C43: FS-13 | D43: TC_FlightSearch_021, TC_FlightSearch_022, TC_FlightSearch_023, TC_FlightSearch_024
... C47: FS-17 | D47: TC_FlightSearch_030, TC_FlightSearch_031
...
